Workbook

Sheet 1
P3: Doc No | Q3: Finowise/CRS/002
P4: Rev. No. | Q4: 00
P5: Rev. Date
D8: CLIENT REVIEW SHEET (Financial Success Ladder)
D17: CLIENT NAME

Sheet Summary
B2: FINOWISE | D2: PORTFOLIO SUMMARY | H2: ='1'!$D$17
H5: Today's Wealth
H11: =INDEX('Portfolio Journey'!B125:T127,MATCH('Portfolio Journey'!FB125,'Portfolio Journey'!B125:B127,0),MATCH('Freedom Blueprint'!AA8,'Portfolio Journey'!B5:T5,0))
H18: Live SIP
H24: =INDEX('Portfolio Journey'!B125:T127,MATCH('Portfolio Journey'!FB126,'Portfolio Journey'!B125:B127,0),MATCH('Freedom Blueprint'!AA8,'Portfolio Journey'!B5:T5,0))

Sheet Portfolio Journey
B2: PORTFOLIO JOURNEY | F2: Review Date :
B5: MF | F5: 2023 | G5: 2024 | H5: =G5+1 | I5: =H5+1 | J5: =I5+1 | K5: =J5+1 | L5: =K5+1 | M5: =L5+1 | N5: =M5+1 | O5: =N5+1 | ... T5: =S5+1
B6: NJ | C6: =TEXT(B6,"yyyy") | D6: Portfolio Value | E6: Equity MF
C7: =TEXT(B7,"yyyy") | E7: Hybrid MF
C8: =TEXT(B8,"yyyy") | E8: Debt MF
C9: =TEXT(B9,"yyyy") | E9: Others
C10: =TEXT(B10,"yyyy") | D10: MF SIP | E10: Equity SIP
C11: =TEXT(B11,"yyyy") | E11: Hybrid SIP
C12: =TEXT(B12,"yyyy") | E12: Debt SIP
C13: =TEXT(B13,"yyyy") | E13: Others SIP
D14: NJ MF Portfolio Value | F14: =F6+F7+F8+F9 | G14: =G6+G7+G8+G9 | H14: =H6+H7+H8+H9 | I14: =I6+I7+I8+I9 | J14: =J6+J7+J8+J9 | K14: =K6+K7+K8+K9 | L14: =L6+L7+L8+L9 | M14: =M6+M7+M8+M9 | ... T14: =T6+T7+T8+T9
C15: =TEXT(B15,"yyyy") | D15: NJ MF Live SIP | F15: =+F10+F11+F12+F13 | G15: =+G10+G11+G12+G13 | H15: =+H10+H11+H12+H13 | I15: =+I10+I11+I12+I13 | J15: =+J10+J11+J12+J13 | K15: =+K10+K11+K12+K13 | L15: =+L10+L11+L12+L13 | M15: =+M10+M11+M12+M13 | ... T15: =+T10+T11+T12+T13
B16: Finowise (Advisorkhoj) | C16: =TEXT(B16,"yyyy") | D16: Portfolio Value | E16: Equity MF
C17: =TEXT(B17,"yyyy") | E17: Hybrid MF
C18: =TEXT(B18,"yyyy") | E18: Debt MF
C19: =TEXT(B19,"yyyy") | E19: Others
C20: =TEXT(B20,"yyyy") | D20: MF SIP | E20: Equity SIP
C21: =TEXT(B21,"yyyy") | E21: Hybrid SIP
C22: =TEXT(B22,"yyyy") | E22: Debt SIP
C23: =TEXT(B23,"yyyy") | E23: Others SIP
D24: AdvisorKhoj MF Portfolio Value | F24: =F16+F17+F18+F19 | G24: =G16+G17+G18+G19 | H24: =H16+H17+H18+H19 | I24: =I16+I17+I18+I19 | J24: =J16+J17+J18+J19 | K24: =K16+K17+K18+K19 | L24: =L16+L17+L18+L19 | M24: =M16+M17+M18+M19 | ... T24: =T16+T17+T18+T19
C25: =TEXT(B25,"yyyy") | D25: AdvisorKhoj MF Live SIP | F25: =F20+F21+F22+F23 | G25: =G20+G21+G22+G23 | H25: =H20+H21+H22+H23 | I25: =I20+I21+I22+I23 | J25: =J20+J21+J22+J23 | K25: =K20+K21+K22+K23 | L25: =L20+L21+L22+L23 | M25: =M20+M21+M22+M23 | ... T25: =T20+T21+T22+T23
B26: Anand Rathi | C26: =TEXT(B26,"yyyy") | D26: Portfolio Value | E26: Equity MF
C27: =TEXT(B27,"yyyy") | E27: Hybrid MF
C28: =TEXT(B28,"yyyy") | E28: Debt MF
C29: =TEXT(B29,"yyyy") | E29: Others
C30: =TEXT(B30,"yyyy") | D30: MF SIP | E30: Equity SIP
C31: =TEXT(B31,"yyyy") | E31: Hybrid SIP
C32: =TEXT(B32,"yyyy") | E32: Debt SIP
C33: =TEXT(B33,"yyyy") | E33: Others SIP
D34: Anand Rathi MF Portfolio Value | F34: =F26+F27+F28+F29 | G34: =G26+G27+G28+G29 | H34: =H26+H27+H28+H29 | I34: =I26+I27+I28+I29 | J34: =J26+J27+J28+J29 | K34: =K26+K27+K28+K29 | L34: =L26+L27+L28+L29 | M34: =M26+M27+M28+M29 | ... T34: =T26+T27+T28+T29
C35: =TEXT(B35,"yyyy") | D35: Anand Rathi MF Live SIP | F35: =F30+F31+F32+F33 | G35: =G30+G31+G32+G33 | H35: =H30+H31+H32+H33 | I35: =I30+I31+I32+I33 | J35: =J30+J31+J32+J33 | K35: =K30+K31+K32+K33 | L35: =L30+L31+L32+L33 | M35: =M30+M31+M32+M33 | ... T35: =T30+T31+T32+T33
B36: Direct | C36: =TEXT(B36,"yyyy") | D36: Portfolio Value | E36: Equity MF
C37: =TEXT(B37,"yyyy") | E37: Hybrid MF
C38: =TEXT(B38,"yyyy") | E38: Debt MF
C39: =TEXT(B39,"yyyy") | E39: Others
C40: =TEXT(B40,"yyyy") | D40: MF SIP | E40: Equity SIP
C41: =TEXT(B41,"yyyy") | E41: Hybrid SIP
C42: =TEXT(B42,"yyyy") | E42: Debt SIP
C43: =TEXT(B43,"yyyy") | E43: Others SIP
...

Sheet Ref File
B5: Section A : Personal Information
C8: Name | G8: Mobile | K8: E Mail
C9: ='1'!$D$17
C11: Date of Birth | G11: Age (Yrs) | K11: Occupation
G12: =DATEDIF(C12,TODAY(),"Y")
C14: City | G14: Country | K14: RM Name
AA15: =YEAR(#REF!)
B19: In How Many Years from Now, You want to Achieve Financial Freedom ? | M19: 10 | Q19: =M19
Q21: =IF(Q19<3,6%,IF(Q19<6,8%,IF(Q19<10,10%,12%)))
B22: Section B : Six Levels to Financial Success Ladder
B23: Target Freedom Wealth Magic Numbers to achieve Your Financial Freedom
C25: Level | E25: Financial Freedom Stage | G25: Freedom Wealth Magic Number | I25: Monthly Passive Income (For Lifetime) | K25: Option # 1 | M25: Option # 2
K26: Required Monthly Investment | M26: Required Lumpsum Investment
N27: =(1+Q21)^(1/12)-1
C29: Level 1 | E29: Financial Vitality | G29: 10000000 | I29: 50000 | K29: =PMT($N$27,$M$19*12,,-G29,1) | M29: =PV($Q$21,$M$19,,-G29,0)
C31: Level 2 | E31: Financial Security | G31: 20000000 | I31: 100000 | K31: =PMT($N$27,$M$19*12,,-G31,1) | M31: =PV($Q$21,$M$19,,-G31,0)
C33: Level 3 | E33: Financial Independence | G33: 40000000 | I33: 200000 | K33: =PMT($N$27,$M$19*12,,-G33,1) | M33: =PV($Q$21,$M$19,,-G33,0)
C35: Level 4 | E35: Financial Freedom | G35: 80000000 | I35: 500000 | K35: =PMT($N$27,$M$19*12,,-G35,1) | M35: =PV($Q$21,$M$19,,-G35,0)
C37: Level 5 | E37: Financial Abundance | G37: 150000000 | I37: 1000000 | K37: =PMT($N$27,$M$19*12,,-G37,1) | M37: =PV($Q$21,$M$19,,-G37,0)
C39: Level 6 | E39: Financial Legacy | G39: 300000000 | I39: 2000000 | K39: =PMT($N$27,$M$19*12,,-G39,1) | M39: =PV($Q$21,$M$19,,-G39,0)
B42: Section C : Your Current Level of Preparedness
B43: Freedom Wealth Corpus expected through Your Existing Assets and Investments
C45: Sr.No. | E45: Asset Class | G45: Current Investment Value | I45: Monthly Savings / Investments | K45: Expected Returns | L45: Allocation | M45: Expected Freedom Wealth
C47: 1 | E47: Retirement Fund (EPF,GPF,401K etc.) | G47: =INDEX(#REF!,MATCH(#REF!,#REF!,0),MATCH('Ref File'!AA$15,#REF!,0)) | I47: =INDEX(#REF!,MATCH(#REF!,#REF!,0),MATCH('Ref File'!AA$15,#REF!,0)) | J47: =(1+K47)^(1/12)-1 | K47: 0.08 | L47: =M47/$M$77 | M47: =P47+Q47 | P47: =FV(K47,$M$19,,-G47,1) | Q47: =FV(J47,$M$19*12,-I47,,1)
C49: 2 | E49: Public Provident Fund (PPF) | G49: =INDEX(#REF!,MATCH(#REF!,#REF!,0),MATCH('Ref File'!AA$15,#REF!,0)) | I49: =INDEX(#REF!,MATCH(#REF!,#REF!,0),MATCH('Ref File'!AA$15,#REF!,0)) | J49: =(1+K49)^(1/12)-1 | K49: 0.07 | L49: =M49/$M$77 | M49: =P49+Q49 | P49: =FV(K49,$M$19,,-G49,1) | Q49: =FV(J49,$M$19*12,-I49,,1)
C51: 3 | E51: Fixed Deposit (FD) | G51: =INDEX(#REF!,MATCH(#REF!,#REF!,0),MATCH('Ref File'!AA$15,#REF!,0)) | I51: =INDEX(#REF!,MATCH(#REF!,#REF!,0),MATCH('Ref File'!AA$15,#REF!,0)) | J51: =(1+K51)^(1/12)-1 | K51: 0.06 | L51: =M51/$M$77 | M51: =P51+Q51 | P51: =FV(K51,$M$19,,-G51,1) | Q51: =FV(J51,$M$19*12,-I51,,1)
C53: 4 | E53: Debt Mutual Fund | G53: =INDEX(#REF!,MATCH(#REF!,#REF!,0),MATCH('Ref File'!AA$15,#REF!,0)) | I53: =INDEX(#REF!,MATCH(#REF!,#REF!,0),MATCH('Ref File'!AA$15,#REF!,0)) | J53: =(1+K53)^(1/12)-1 | K53: 0.06 | L53: =M53/$M$77 | M53: =P53+Q53 | P53: =FV(K53,$M$19,,-G53,1) | Q53: =FV(J53,$M$19*12,-I53,,1)
C55: 5 | E55: Hybrid Mutual Fund | G55: =INDEX(#REF!,MATCH(#REF!,#REF!,0),MATCH('Ref File'!AA$15,#REF!,0)) | I55: =INDEX(#REF!,MATCH(#REF!,#REF!,0),MATCH('Ref File'!AA$15,#REF!,0)) | J55: =(1+K55)^(1/12)-1 | K55: 0.1 | L55: =M55/$M$77 | M55: =P55+Q55 | P55: =FV(K55,$M$19,,-G55,1) | Q55: =FV(J55,$M$19*12,-I55,,1)
C57: 6 | E57: Equity Mutual Fund | G57: =INDEX(#REF!,MATCH(#REF!,#REF!,0),MATCH('Ref File'!AA$15,#REF!,0)) | I57: =INDEX(#REF!,MATCH(#REF!,#REF!,0),MATCH('Ref File'!AA$15,#REF!,0)) | J57: =(1+K57)^(1/12)-1 | K57: 0.12 | L57: =M57/$M$77 | M57: =P57+Q57 | P57: =FV(K57,$M$19,,-G57,1) | Q57: =FV(J57,$M$19*12,-I57,,1)
C59: 7 | E59: Other Mutual Fund | G59: =INDEX(#REF!,MATCH(#REF!,#REF!,0),MATCH('Ref File'!AA$15,#REF!,0)) | I59: =INDEX(#REF!,MATCH(#REF!,#REF!,0),MATCH('Ref File'!AA$15,#REF!,0)) | J59: =(1+K59)^(1/12)-1 | K59: 0.09 | L59: =M59/$M$77 | M59: =P59+Q59 | P59: =FV(K59,$M$19,,-G59,1) | Q59: =FV(J59,$M$19*12,-I59,,1)
C61: 8 | E61: National Pension Scheme (NPS) | G61: =INDEX(#REF!,MATCH(#REF!,#REF!,0),MATCH('Ref File'!AA$15,#REF!,0)) | I61: =INDEX(#REF!,MATCH(#REF!,#REF!,0),MATCH('Ref File'!AA$15,#REF!,0)) | J61: =(1+K61)^(1/12)-1 | K61: 0.1 | L61: =M61/$M$77 | M61: =P61+Q61 | P61: =FV(K61,$M$19,,-G61,1) | Q61: =FV(J61,$M$19*12,-I61,,1)
C63: 9 | E63: Unit Linked Insurance Plan (ULIP) | G63: =INDEX(#REF!,MATCH(#REF!,#REF!,0),MATCH('Ref File'!AA$15,#REF!,0)) | I63: =INDEX(#REF!,MATCH(#REF!,#REF!,0),MATCH('Ref File'!AA$15,#REF!,0)) | J63: =(1+K63)^(1/12)-1 | K63: 0.1 | L63: =M63/$M$77 | M63: =P63+Q63 | P63: =FV(K63,$M$19,,-G63,1) | Q63: =FV(J63,$M$19*12,-I63,,1)
C65: 10 | E65: Equity Stocks | G65: =INDEX(#REF!,MATCH(#REF!,#REF!,0),MATCH('Ref File'!AA$15,#REF!,0)) | I65: =INDEX(#REF!,MATCH(#REF!,#REF!,0),MATCH('Ref File'!AA$15,#REF!,0)) | J65: =(1+K65)^(1/12)-1 | K65: 0.14 | L65: =M65/$M$77 | M65: =P65+Q65 | P65: =FV(K65,$M$19,,-G65,1) | Q65: =FV(J65,$M$19*12,-I65,,1)
C67: 11 | E67: Investment Property | G67: =INDEX(#REF!,MATCH(#REF!,#REF!,0),MATCH('Ref File'!AA$15,#REF!,0)) | J67: =(1+K67)^(1/12)-1 | K67: 0.06 | L67: =M67/$M$77 | M67: =P67+Q67 | P67: =FV(K67,$M$19,,-G67,1) | Q67: =FV(J67,$M$19*12,-I67,,1)
C69: 12 | E69: Gold as investment | G69: =INDEX(#REF!,MATCH(#REF!,#REF!,0),MATCH('Ref File'!AA$15,#REF!,0)) | I69: =INDEX(#REF!,MATCH(#REF!,#REF!,0),MATCH('Ref File'!AA$15,#REF!,0)) | J69: =(1+K69)^(1/12)-1 | K69: 0.08 | L69: =M69/$M$77 | M69: =P69+Q69 | P69: =FV(K69,$M$19,,-G69,1) | Q69: =FV(J69,$M$19*12,-I69,,1)
C71: 13 | E71: Traditional Insurance Policy | G71: =INDEX(#REF!,MATCH(#REF!,#REF!,0),MATCH('Ref File'!AA$15,#REF!,0)) | I71: =INDEX(#REF!,MATCH(#REF!,#REF!,0),MATCH('Ref File'!AA$15,#REF!,0)) | J71: =(1+K71)^(1/12)-1 | K71: 0.05 | L71: =M71/$M$77 | M71: =P71+Q71 | P71: =FV(K71,$M$19,,-G71,1) | Q71: =FV(J71,$M$19*12,-I71,,1)
C73: 14 | E73: Other Investments if any | G73: =INDEX(#REF!,MATCH(#REF!,#REF!,0),MATCH('Ref File'!AA$15,#REF!,0)) | I73: =INDEX(#REF!,MATCH(#REF!,#REF!,0),MATCH('Ref File'!AA$15,#REF!,0)) | J73: =(1+K73)^(1/12)-1 | K73: 0.08 | L73: =M73/$M$77 | M73: =P73+Q73 | P73: =FV(K73,$M$19,,-G73,1) | Q73: =FV(J73,$M$19*12,-I73,,1)
C75: 15 | E75: Freedom Wealth Portfolio | J75: =(1+K75)^(1/12)-1 | K75: 0.12 | L75: =M75/$M$77 | M75: =P75+Q75 | P75: =FV(K75,$M$19,,-G75,1) | Q75: =FV(J75,$M$19*12,-I75,,1)
E77: Total | G77: =SUM(G47:G69) | I77: =SUM(I47:I69) | K77: =(K47*L47)+(K49*L49)+(K51*L51)+(K53*L53)+(K55*L55)+(K57*L57)+(K61*L61)+(K63*L63)+(K65*L65)+(K67*L67)+(K69*L69)+(K71*L71)+(K75*L75)+(K73*L73) | M77: =SUM(M47:M73)
B81: Section D : Freedom Wealth Target
...

Sheet SUMMARY PORTFOLIO
C1: NJ | M1: REDVISION | W1: ANAND RATHI | AC1: EQUITY SHARES | AG1: NEXT FREEDOM LIFEX | AQ1: FINOWISE TOTAL PORTFOLIO | AU1: SELF MF & STOCKS INVESTMENT PORTFOLIO | BB1: Self Small Savings | BM1: GRAND TOTAL
A2: DATE | B2: INVESTOR'S NAME | C2: EQUITY MF | D2: EQUITY SIP | E2: HYBRID MF | F2: HYBRID SIP | G2: DEBT MF | H2: DEBT SIP | I2: OTHER MF | J2: OTHER SIP | K2: NJ LIVE SIP | L2: TOTAL NJ MF PORTFOLIO VALUE | M2: EQUITY MF | N2: EQUITY SIP | O2: HYBRID MF | P2: HYBRID SIP | Q2: DEBT MF | R2: DEBT SIP | S2: OTHER MF | T2: OTHER SIP | U2: REDVISION LIVE SIP | V2: TOTAL REDVISION MF PORTFOLIO VALUE | W2: EQUITY MF | X2: HYBRID MF | Y2: DEBT MF | Z2: OTHER MF | AA2: AR LIVE SIP | AB2: TOTAL AR MF PORTFOLIO VALUE | AC2: MOTILAL OSWAL | AD2: OMNISCIENCE | AE2: PIPER SERICA | AF2: TOTAL EQUITY SHARES PORTFOLIO VALUE | AG2: EQUITY MF | AH2: EQUITY SIP | AI2: HYBRID MF | AJ2: HYBRID SIP | AK2: DEBT MF | AL2: DEBT SIP | AM2: OTHER MF | AN2: OTHER MF SIP | AO2: NFLX LIVE SIP | AP2: TOTAL NEXT LEVEL FREEDOM LIFE X MF | AQ2: TOTAL LIVE SIP | AR2: TOTAL WEALTH | AS2: Redemption Value | AT2: Remark (Reason for redemption) | AU2: SHARES | AV2: EQUITY MF | AW2: HYBRID MF | AX2: DEBT MF | AY2: OTHER MF | AZ2: SELF MF & STOCKS LIVE SIP | BA2: TOTAL SELF MF & STOCKS PORTFOLIO VALUE | BB2: EPF CURRENT VALUE | BC2: EPF CURRENT VALUE | BD2: EPF Monthly Deduction | BE2: PPF CURRENT VALUE | BF2: PPF Annual Contribution | BG2: NPS CURRENT Value | BH2: NPS Annual Contribution | BI2: Total Monthly Small-Self Savings | BJ2: Total Small-Self Saving Portfolio Value | BK2: Systematic Withdrawal Plan (SWP) | BL2: Total Monthly Avg Financial Savings | BM2: Totl Invested Value | BN2: Total Financial Wealth | BO2: Total Gain

Sheet DETAILED PORTFOLIO
B1: SCHEME-WISE SUMMARY
A2: Sr. No. | B2: Scheme | C2: Sub Type | D2: Investment Value | E2: Div.ReInvesting. (₹) | F2: No. of Units | G2: Current Portfolio Value (₹) | H2: Div R (₹) | I2: Div P (₹) | J2: Total (₹) | K2: Annualized Return (%) | L2: Abs. Return(%) | M2: %Holding | N2: Tenure | O2: Live SIP Amount | P2: New SIP as on 21-06-2025 | Q2: STP IN Amount | R2: STP OUT Amount | S2: SWP | T2: Remarks | U2: Suggestions

Sheet Freedom Blueprint
B4: Section A : Personal Information | M4: Date : | N4: ='Portfolio Journey'!G2
C7: Name | G7: Mobile | I7: E Mail | M7: Occupation
C8: ='1'!$D$17 | AA8: =YEAR('Portfolio Journey'!G2)
C10: Date of Birth | G10: Age (Yrs) | I10: City | K10: Country | M10: RM Name
G11: =IF(C11="","",DATEDIF(C11,TODAY(),"Y"))
B14: In How Many Years from Now, You want to Start Your Monthly Passive Income | O14: 10
B16: Section B : Six Levels to Financial Success Ladder
B17: Target Wealth Magic Number to achieve Your Desired Level of Financial Success
C19: Financial Success Level | E19: Financial Success Stage | G19: Required Wealth Magic Number | I19: The Meaning , Power and Purpose of Each Level of Wealth Corpus
C23: Level 1 | E23: Financial Vitality | G23: 10000000 | I23: Empowers you to maintain a lifestyle worth Rs 50,000 per month | R23: =PV(6%,O$14,,-#REF!,0) | S23: =ROUNDUP(R23,-3) | U23: =(#REF!*12)/G23
C25: Level 2 | E25: Financial Security | G25: 20000000 | I25: Empowers you to maintain a lifestyle worth Rs 1,00,000 per month | R25: =PV(6%,O$14,,-#REF!,0) | S25: =ROUNDUP(R25,-3) | U25: =(#REF!*12)/G25
C27: Level 3 | E27: Financial Independence | G27: 40000000 | I27: Empowers you to maintain a lifestyle worth Rs 2,00,000 per month | R27: =PV(6%,O$14,,-#REF!,0) | S27: =ROUNDUP(R27,-3) | U27: =(#REF!*12)/G27
C29: Level 4 | E29: Financial Freedom | G29: 80000000 | I29: Empowers you to maintain a lifestyle worth Rs 4,00,000 per month | R29: =PV(6%,O$14,,-#REF!,0) | S29: =ROUNDUP(R29,-3) | U29: =(#REF!*12)/G29
C31: Level 5 | E31: Financial Abundance | G31: 160000000 | I31: Empowers you to live a lifestyle of Rs 8 Lakh per month and also You can Leave behind a Legacy Corpus for Your family | R31: =PV(6%,O$14,,-#REF!,0) | S31: =ROUNDUP(R31,-3) | U31: =(#REF!*12)/G31
C33: Level 6 | E33: Financial Legacy | G33: 320000000 | I33: Empowers you to live a lifestyle of Rs 15 Lakhs per month and also You can Leave behind a Legacy Corpus for Your family and Social Cause that you want to Support | R33: =PV(6%,O$14,,-#REF!,0) | S33: =ROUNDUP(R33,-3) | U33: =(#REF!*12)/G33
B37: Section C : Your Current Level of Preparedness
B38: Freedom Wealth Corpus expected through Your Existing Assets and Investments
C40: Sr.No. | E40: Asset Description | G40: Current Investment Value | I40: Monthly Savings / Investments | K40: Expected Returns | M40: Asset Allocation | O40: Expected Freedom Wealth
C42: 1 | E42: Employee Provident Fund (EPF) | G42: =INDEX('Portfolio Journey'!B95:T119,MATCH('Portfolio Journey'!FB96,'Portfolio Journey'!D95:D119,0),MATCH('Freedom Blueprint'!AA8,'Portfolio Journey'!B95:T95,0)) | I42: =INDEX('Portfolio Journey'!B95:T119,MATCH('Portfolio Journey'!FB97,'Portfolio Journey'!D95:D119,0),MATCH('Freedom Blueprint'!AA8,'Portfolio Journey'!B95:T95,0)) | K42: 0.07 | L42: =(1+K42)^(1/12)-1 | M42: =IF(O42=0,"0% ",O42/$O$78) | O42: =R42+S42 | R42: =FV(K42,$O$14,,-G42,1) | S42: =FV(L42,$O$14*12,-I42,,1)
C44: 2 | E44: Gratuity | G44: =INDEX('Portfolio Journey'!B95:T119,MATCH('Portfolio Journey'!FB98,'Portfolio Journey'!D95:D119,0),MATCH('Freedom Blueprint'!AA8,'Portfolio Journey'!B95:T95,0)) | K44: 0 | L44: =(1+K44)^(1/12)-1 | M44: =IF(O44=0,"0% ",O44/$O$78) -> 0% | O44: =R44+S44 | R44: =FV(K44,$O$14,,-G44,1) | S44: =FV(L44,$O$14*12,-I44,,1)
C46: 3 | E46: Superannuation | G46: =INDEX('Portfolio Journey'!B95:T119,MATCH('Portfolio Journey'!FB100,'Portfolio Journey'!D95:D119,0),MATCH('Freedom Blueprint'!AA8,'Portfolio Journey'!B95:T95,0)) | I46: =INDEX('Portfolio Journey'!B95:T119,MATCH('Portfolio Journey'!FB101,'Portfolio Journey'!D95:D119,0),MATCH('Freedom Blueprint'!AA8,'Portfolio Journey'!B95:T95,0)) | K46: 0.05 | L46: =(1+K46)^(1/12)-1 | M46: =IF(O46=0,"0% ",O46/$O$78) -> 0% | O46: =R46+S46 | R46: =FV(K46,$O$14,,-G46,1) | S46: =FV(L46,$O$14*12,-I46,,1)
C48: 4 | E48: Public Provident Fund (PPF) | G48: =INDEX('Portfolio Journey'!B95:T119,MATCH('Portfolio Journey'!FB102,'Portfolio Journey'!D95:D119,0),MATCH('Freedom Blueprint'!AA8,'Portfolio Journey'!B95:T95,0)) | I48: =INDEX('Portfolio Journey'!B95:T119,MATCH('Portfolio Journey'!FB103,'Portfolio Journey'!D95:D119,0),MATCH('Freedom Blueprint'!AA8,'Portfolio Journey'!B95:T95,0)) | K48: 0.071 | L48: =(1+K48)^(1/12)-1 | M48: =IF(O48=0,"0% ",O48/$O$78) | O48: =R48+S48 | R48: =FV(K48,$O$14,,-G48,1) | S48: =FV(L48,$O$14*12,-I48,,1)
C50: 5 | E50: Fixed Deposit (FD) | G50: =INDEX('Portfolio Journey'!B95:T119,MATCH('Portfolio Journey'!FB104,'Portfolio Journey'!D95:D119,0),MATCH('Freedom Blueprint'!AA8,'Portfolio Journey'!B95:T95,0)) | I50: =INDEX('Portfolio Journey'!B95:T119,MATCH('Portfolio Journey'!FB105,'Portfolio Journey'!D95:D119,0),MATCH('Freedom Blueprint'!AA8,'Portfolio Journey'!B95:T95,0)) | K50: 0.06 | L50: =(1+K50)^(1/12)-1 | M50: =IF(O50=0,"0% ",O50/$O$78) -> 0% | O50: =R50+S50 | R50: =FV(K50,$O$14,,-G50,1) | S50: =FV(L50,$O$14*12,-I50,,1)
C52: 6 | E52: Debt Mutual Fund | G52: =INDEX('Portfolio Journey'!B56:T63,MATCH('Portfolio Journey'!FB58,'Portfolio Journey'!E56:E63,0),MATCH('Freedom Blueprint'!AA8,'Portfolio Journey'!B5:T5,0)) | I52: =INDEX('Portfolio Journey'!B56:T63,MATCH('Portfolio Journey'!FB62,'Portfolio Journey'!E56:E63,0),MATCH('Freedom Blueprint'!AA8,'Portfolio Journey'!B5:T5,0)) | K52: 0.06 | L52: =(1+K52)^(1/12)-1 | M52: =IF(O52=0,"0% ",O52/$O$78) | O52: =R52+S52 | R52: =FV(K52,$O$14,,-G52,1) | S52: =FV(L52,$O$14*12,-I52,,1)
C54: 7 | E54: Hybrid Mutual Fund | G54: =INDEX('Portfolio Journey'!B56:T63,MATCH('Portfolio Journey'!FB57,'Portfolio Journey'!E56:E63,0),MATCH('Freedom Blueprint'!AA8,'Portfolio Journey'!B5:T5,0)) | I54: =INDEX('Portfolio Journey'!B56:T63,MATCH('Portfolio Journey'!FB61,'Portfolio Journey'!E56:E63,0),MATCH('Freedom Blueprint'!AA8,'Portfolio Journey'!B5:T5,0)) | K54: 0.1 | L54: =(1+K54)^(1/12)-1 | M54: =IF(O54=0,"0% ",O54/$O$78) | O54: =R54+S54 | R54: =FV(K54,$O$14,,-G54,1) | S54: =FV(L54,$O$14*12,-I54,,1)
C56: 8 | E56: Equity Mutual Fund | G56: =INDEX('Portfolio Journey'!B56:T63,MATCH('Portfolio Journey'!FB56,'Portfolio Journey'!E56:E63,0),MATCH('Freedom Blueprint'!AA8,'Portfolio Journey'!B5:T5,0)) | I56: =INDEX('Portfolio Journey'!B56:T63,MATCH('Portfolio Journey'!FB60,'Portfolio Journey'!E56:E63,0),MATCH('Freedom Blueprint'!AA8,'Portfolio Journey'!B5:T5,0)) | K56: 0.12 | L56: =(1+K56)^(1/12)-1 | M56: =IF(O56=0,"0% ",O56/$O$78) | O56: =R56+S56 | R56: =FV(K56,$O$14,,-G56,1) | S56: =FV(L56,$O$14*12,-I56,,1)
C58: 9 | E58: Other Mutual Fund | G58: =INDEX('Portfolio Journey'!B56:T63,MATCH('Portfolio Journey'!FB59,'Portfolio Journey'!E56:E63,0),MATCH('Freedom Blueprint'!AA8,'Portfolio Journey'!B5:T5,0)) | I58: =INDEX('Portfolio Journey'!B56:T63,MATCH('Portfolio Journey'!FB63,'Portfolio Journey'!E56:E63,0),MATCH('Freedom Blueprint'!AA8,'Portfolio Journey'!B5:T5,0)) | K58: 0.09 | L58: =(1+K58)^(1/12)-1 | M58: =IF(O58=0,"0% ",O58/$O$78) | O58: =R58+S58 | R58: =FV(K58,$O$14,,-G58,1) | S58: =FV(L58,$O$14*12,-I58,,1)
C60: 10 | E60: NPS - Self | G60: =INDEX('Portfolio Journey'!B95:T119,MATCH('Portfolio Journey'!FB106,'Portfolio Journey'!D95:D119,0),MATCH('Freedom Blueprint'!AA8,'Portfolio Journey'!B95:T95,0)) | I60: =INDEX('Portfolio Journey'!B95:T119,MATCH('Portfolio Journey'!FB107,'Portfolio Journey'!D95:D119,0),MATCH('Freedom Blueprint'!AA8,'Portfolio Journey'!B95:T95,0)) | K60: 0.1 | L60: =(1+K60)^(1/12)-1 | M60: =IF(O60=0,"0% ",O60/$O$78) -> 0% | O60: =R60+S60 | R60: =FV(K60,$O$14,,-G60,1) | S60: =FV(L60,$O$14*12,-I60,,1)
C62: 11 | E62: NPS - Employer | G62: =INDEX('Portfolio Journey'!B95:T119,MATCH('Portfolio Journey'!FB108,'Portfolio Journey'!D95:D119,0),MATCH('Freedom Blueprint'!AA8,'Portfolio Journey'!B95:T95,0)) | I62: =INDEX('Portfolio Journey'!B95:T119,MATCH('Portfolio Journey'!FB109,'Portfolio Journey'!D95:D119,0),MATCH('Freedom Blueprint'!AA8,'Portfolio Journey'!B95:T95,0)) | K62: 0.1 | L62: =(1+K62)^(1/12)-1 | M62: =IF(O62=0,"0% ",O62/$O$78) -> 0% | O62: =R62+S62 | R62: =FV(K62,$O$14,,-G62,1) | S62: =FV(L62,$O$14*12,-I62,,1)
C64: 12 | E64: Unit Linked Insurance Plan (ULIP) | G64: =INDEX('Portfolio Journey'!B95:T119,MATCH('Portfolio Journey'!FB110,'Portfolio Journey'!D95:D119,0),MATCH('Freedom Blueprint'!AA8,'Portfolio Journey'!B95:T95,0)) | I64: =INDEX('Portfolio Journey'!B95:T119,MATCH('Portfolio Journey'!FB111,'Portfolio Journey'!D95:D119,0),MATCH('Freedom Blueprint'!AA8,'Portfolio Journey'!B95:T95,0)) | K64: 0.05 | L64: =(1+K64)^(1/12)-1 | M64: =IF(O64=0,"0% ",O64/$O$78) | O64: =R64+S64 | R64: =FV(K64,$O$14,,-G64,1) | S64: =FV(L64,$O$14*12,-I64,,1)
C66: 13 | E66: Equity Stocks | G66: =INDEX('Portfolio Journey'!B89:T90,MATCH('Portfolio Journey'!FB89,'Portfolio Journey'!B89:B90,0),MATCH('Freedom Blueprint'!AA8,'Portfolio Journey'!B5:T5,0)) | I66: =INDEX('Portfolio Journey'!B89:T90,MATCH('Portfolio Journey'!FB90,'Portfolio Journey'!B89:B90,0),MATCH('Freedom Blueprint'!AA8,'Portfolio Journey'!B5:T5,0)) | K66: 0.14 | L66: =(1+K66)^(1/12)-1 | M66: =IF(O66=0,"0% ",O66/$O$78) | O66: =R66+S66 | R66: =FV(K66,$O$14,,-G66,1) | S66: =FV(L66,$O$14*12,-I66,,1)
C68: 14 | E68: Investment Property | G68: 0 | K68: 0.06 | L68: =(1+K68)^(1/12)-1 | M68: =IF(O68=0,"0% ",O68/$O$78) -> 0% | O68: =R68+S68 | R68: =FV(K68,$O$14,,-G68,1) | S68: =FV(L68,$O$14*12,-I68,,1)
C70: 15 | E70: Gold as investment | G70: 0 | I70: =INDEX('Portfolio Journey'!B95:T119,MATCH('Portfolio Journey'!FB115,'Portfolio Journey'!D95:D119,0),MATCH('Freedom Blueprint'!AA8,'Portfolio Journey'!B95:T95,0)) | K70: 0.08 | L70: =(1+K70)^(1/12)-1 | M70: =IF(O70=0,"0% ",O70/$O$78) -> 0% | O70: =R70+S70 | R70: =FV(K70,$O$14,,-G70,1) | S70: =FV(L70,$O$14*12,-I70,,1)
C72: 16 | E72: Traditional Insurance Policy | G72: =INDEX('Portfolio Journey'!B95:T119,MATCH('Portfolio Journey'!FB116,'Portfolio Journey'!D95:D119,0),MATCH('Freedom Blueprint'!AA8,'Portfolio Journey'!B95:T95,0)) | I72: =INDEX('Portfolio Journey'!B95:T119,MATCH('Portfolio Journey'!FB117,'Portfolio Journey'!D95:D119,0),MATCH('Freedom Blueprint'!AA8,'Portfolio Journey'!B95:T95,0)) | K72: 0.05 | L72: =(1+K72)^(1/12)-1 | M72: =IF(O72=0,"0% ",O72/$O$78) -> 0% | O72: =R72+S72 | R72: =FV(K72,$O$14,,-G72,1) | S72: =FV(L72,$O$14*12,-I72,,1)
C74: 17 | E74: Other Investments if any | G74: =INDEX('Portfolio Journey'!B95:T119,MATCH('Portfolio Journey'!FB118,'Portfolio Journey'!D95:D119,0),MATCH('Freedom Blueprint'!AA8,'Portfolio Journey'!B95:T95,0)) | I74: =INDEX('Portfolio Journey'!B95:T119,MATCH('Portfolio Journey'!FB119,'Portfolio Journey'!D95:D119,0),MATCH('Freedom Blueprint'!AA8,'Portfolio Journey'!B95:T95,0)) | K74: 0.07 | L74: =(1+K74)^(1/12)-1 | M74: =IF(O74=0,"0% ",O74/$O$78) | O74: =R74+S74 | R74: =FV(K74,$O$14,,-G74,1) | S74: =FV(L74,$O$14*12,-I74,,1)
C76: 18 | E76: Freedom Wealth Portfolio | K76: 0.12 | L76: =(1+K76)^(1/12)-1 | M76: =IF(O76=0,"0% ",O76/$O$78) -> 0% | O76: =R76+S76 | R76: =FV(K76,$O$14,,-G76,1) | S76: =FV(L76,$O$14*12,-I76,,1)
E78: Total | G78: =SUM(G42:G76) | I78: =SUM(I42:I76) | K78: =(K42*M42)+(K44*M44)+(K46*M46)+(K48*M48)+(K50*M50)+(K52*M52)+(K54*M54)+(K56*M56)+(K58*M58)+(K60*M60)+(K62*M62)+(K64*M64)+(K66*M66)+(K68*M68)+(K70*M70)+(K72*M72)+(K74*M74)+(K76*M76) | M78: =SUM(M42:M76) | O78: =SUM(O42:O76)
B82: Section D : Freedom Wealth Target
B83: Freedom Wealth GAP Corpus required to achieve Your Desired Level of Financial Success
C85: Financial Success Level | E85: Financial Success Stage | G85: Required Wealth Magic Number | I85: Expected Wealth (Through existing assets & investments) | K85: GAP Wealth Corpus | BF85: REF.
...

Sheet Sheet2
C3: Financial Success Ladder
C4: FSL Level | D4: Passive Income for Current SOL (Standard of Living) | E4: Tax Adjusted Passive Income | F4: Inflation Adjusted Passive Income | G4: Passive Income for Desired SOL (Standard of Living) | H4: Legacy Corpus for Family | I4: Legacy Corpus for Social Cause
C5: Level 1
C6: Level 2
C7: Level 3
C8: Level 4
C9: Level 5
C10: Level 6

Sheet Discussion
B2: Minutes of Meeting Summary
A3: DATE:
